Workbook
Name Slicer_Category: #N/A
Name Slicer_Category1: #N/A
Name Slicer_Category2: #N/A
Name Slicer_City: #N/A
Name Slicer_Payment_Method: #N/A
Name Slicer_Payment_Method1: #N/A
Name Slicer_Product_Name: #N/A
Name Slicer_Region: #N/A
Name Slicer_Segment: #N/A
Name Slicer_State: #N/A

Sheet DataSet
A1: Order ID | B1: Order Date | C1: Ship Date | D1: Customer ID | E1: Customer Name | F1: Segment | G1: City | H1: State | I1: Region | J1: Category | K1: Product Name | L1: Sales | M1: Quantity | N1: Discount | O1: Profit | P1: Payment Method
A2: ORD-2025-00001 | B2: 45946 | C2: 45947 | D2: CUST-0174 | E2: Kiara Shah | F2: Home Office | G2: Bhavnagar | H2: Gujarat | I2: West | J2: Furniture | K2: Study Table | L2: 26000 | M2: 4 | N2: 0 | O2: 4901.45 | P2: Cash
A3: ORD-2024-00002 | B3: 45324 | C3: 45948 | D3: CUST-0167 | E3: Kiara Panjwani | F3: Consumer | G3: Bhavnagar | H3: Gujarat | I3: West | J3: Office Supplies | K3: Pens Set | L3: 102 | M3: 1 | N3: 0.15 | O3: 31.19 | P3: Cash
A4: ORD-2025-00003 | B4: 45895 | C4: 45949 | D4: CUST-0056 | E4: Aditya Shah | F4: Consumer | G4: Hyderabad | H4: Telangana | I4: South | J4: Electronics | K4: Keyboard | L4: 6317.5 | M4: 7 | N4: 0.05 | O4: 1896.85 | P4: Cash
A5: ORD-2024-00004 | B5: 45391 | C5: 45950 | D5: CUST-0138 | E5: Anaya Sheikh | F5: Corporate | G5: Kolkata | H5: West Bengal | I5: East | J5: Furniture | K5: Drawer Unit | L5: 15500 | M5: 5 | N5: 0 | O5: 2949.18 | P5: UPI
A6: ORD-2025-00005 | B6: 45857 | C6: 45951 | D6: CUST-0170 | E6: Myra Iyer | F6: Corporate | G6: Kolkata | H6: West Bengal | I6: East | J6: Furniture | K6: Drawer Unit | L6: 9920 | M6: 4 | N6: 0.2 | O6: 3292.6 | P6: UPI
A7: ORD-2026-00006 | B7: 46167 | C7: 45952 | D7: CUST-0094 | E7: Isha Trivedi | F7: Corporate | G7: Kolkata | H7: West Bengal | I7: East | J7: Electronics | K7: USB Drive | L7: 2475 | M7: 5 | N7: 0.1 | O7: 494.31 | P7: Credit Card
A8: ORD-2025-00007 | B8: 45978 | C8: 45953 | D8: CUST-0042 | E8: Rohan Panjwani | F8: Corporate | G8: Chennai | H8: Tamil Nadu | I8: South | J8: Electronics | K8: Monitor | L8: 21675 | M8: 3 | N8: 0.15 | O8: 3639.82 | P8: Net Banking
A9: ORD-2024-00008 | B9: 45516 | C9: 45954 | D9: CUST-0017 | E9: Reyansh Sheikh | F9: Home Office | G9: Mumbai | H9: Maharashtra | I9: West | J9: Electronics | K9: Keyboard | L9: 902.5 | M9: 1 | N9: 0.05 | O9: 242.05 | P9: Debit Card
A10: ORD-2024-00009 | B10: 45509 | C10: 45955 | D10: CUST-0191 | E10: Kiara Soni | F10: Corporate | G10: Jaipur | H10: Rajasthan | I10: North | J10: Accessories | K10: Power Bank | L10: 4560 | M10: 3 | N10: 0.05 | O10: 1533.05 | P10: Net Banking
A11: ORD-2025-00010 | B11: 45730 | C11: 45956 | D11: CUST-0194 | E11: Diya Rao | F11: Consumer | G11: Pune | H11: Maharashtra | I11: West | J11: Furniture | K11: Study Table | L11: 16575 | M11: 3 | N11: 0.15 | O11: 3798.76 | P11: Credit Card
A12: ORD-2025-00011 | B12: 45934 | C12: 45957 | D12: CUST-0120 | E12: Dev Joshi | F12: Home Office | G12: Hyderabad | H12: Telangana | I12: South | J12: Accessories | K12: Cable Organizer | L12: 396 | M12: 2 | N12: 0.1 | O12: 105.25 | P12: UPI
A13: ORD-2025-00012 | B13: 45988 | C13: 45958 | D13: CUST-0117 | E13: Aarav Verma | F13: Home Office | G13: Bhavnagar | H13: Gujarat | I13: West | J13: Furniture | K13: Bookshelf | L13: 5320 | M13: 2 | N13: 0.05 | O13: 1380.33 | P13: Debit Card
... A1001: ORD-2024-01000 | B1001: 45582 | C1001: 45587 | D1001: CUST-0227 | E1001: Kabir Dave | F1001: Home Office | G1001: Vadodara | H1001: Gujarat | I1001: West | J1001: Office Supplies | K1001: Notebook Pack | L1001: 720 | M1001: 5 | N1001: 0.2 | O1001: 138.2 | P1001: Cash

Sheet Data Analysis & Visualisation
C2: Total sales from all City | J2: Total sales from all State | Q2: Total sales from Region | W2: Category wise total sales | AC2: Category wise Quantity | AJ2: CustomerID vs Payment Method | AO2: Region wise Payment Method
C3: City | D3: Sum of Sales | J3: State | K3: Sum of Sales | Q3: Region | R3: Sum of Sales | W3: Category | X3: Sum of Sales | AC3: Category | AD3: Count of Quantity | AJ3: Payment Method | AK3: Count of Customer ID | AO3: Region | AP3: Payment Method | AQ3: Count of Payment Method
C4: Ahmedabad | D4: 428509.5 | J4: Delhi | K4: 394535.5 | Q4: Central | R4: 380218 | W4: Accessories | X4: 1097218.5 | AC4: Accessories | AD4: 268 | AJ4: Cash | AK4: 193 | AO4: Central | AP4: Cash | AQ4: 18
C5: Bengaluru | D5: 575877.5 | J5: Gujarat | K5: 2660752.5 | Q5: East | R5: 418438 | W5: Electronics | X5: 2622957.5 | AC5: Electronics | AD5: 251 | AJ5: Credit Card | AK5: 192 | AP5: Credit Card | AQ5: 9
C6: Bhavnagar | D6: 548171.5 | J6: Karnataka | K6: 575877.5 | Q6: North | R6: 1243547.5 | W6: Furniture | X6: 3073800 | AC6: Furniture | AD6: 238 | AJ6: Debit Card | AK6: 191 | AP6: Debit Card | AQ6: 14
C7: Chennai | D7: 546874 | J7: Madhya Pradesh | K7: 380218 | Q7: South | R7: 1399778 | W7: Office Supplies | X7: 180372 | AC7: Office Supplies | AD7: 243 | AJ7: Net Banking | AK7: 199 | AP7: Net Banking | AQ7: 5
C8: Delhi | D8: 394535.5 | J8: Maharashtra | K8: 871614 | Q8: West | R8: 3532366.5 | W8: Grand Total | X8: 6974348 | AC8: Grand Total | AD8: 1000 | AJ8: UPI | AK8: 225 | AP8: UPI | AQ8: 13
C9: Hyderabad | D9: 277026.5 | J9: Rajasthan | K9: 432785.5 | Q9: Grand Total | R9: 6974348 | AJ9: Grand Total | AK9: 1000 | AO9: Central Total | AQ9: 59
C10: Indore | D10: 380218 | J10: Tamil Nadu | K10: 546874 | AO10: East | AP10: Cash | AQ10: 12
C11: Jaipur | D11: 432785.5 | J11: Telangana | K11: 277026.5 | AP11: Credit Card | AQ11: 18
C12: Kolkata | D12: 418438 | J12: Uttar Pradesh | K12: 416226.5 | AP12: Debit Card | AQ12: 14
C13: Lucknow | D13: 416226.5 | J13: West Bengal | K13: 418438 | AP13: Net Banking | AQ13: 14
C14: Mumbai | D14: 376616.5 | J14: Grand Total | K14: 6974348 | AP14: UPI | AQ14: 12
C15: Pune | D15: 494997.5 | AO15: East Total | AQ15: 70
C16: Rajkot | D16: 452242 | AO16: North | AP16: Cash | AQ16: 32
C17: Surat | D17: 564353 | AP17: Credit Card | AQ17: 43
C18: Vadodara | D18: 667476.5 | AP18: Debit Card | AQ18: 35
C19: Grand Total | D19: 6974348 | AP19: Net Banking | AQ19: 34
AP20: UPI | AQ20: 41
AO21: North Total | AQ21: 185
AO22: South | AP22: Cash | AQ22: 39
AP23: Credit Card | AQ23: 45
AP24: Debit Card | AQ24: 30
AP25: Net Banking | AQ25: 54
AP26: UPI | AQ26: 41
AO27: South Total | AQ27: 209
AO28: West | AP28: Cash | AQ28: 92
AP29: Credit Card | AQ29: 77
AP30: Debit Card | AQ30: 98
AP31: Net Banking | AQ31: 92
AP32: UPI | AQ32: 118
AO33: West Total | AQ33: 477
AO34: Grand Total | AQ34: 1000
C37: Sales collected by Payent method | J37: Product Wise Quantity | N37: Category wise total Profit | T37: Segment wise City
C38: Payment Method | D38: Sum of Sales | J38: Product Name | K38: Count of Quantity | N38: Category | O38: Sum of Profit | T38: Segment | U38: Count of City
C39: Cash | D39: 1245510.5 | J39: Bookshelf | K39: 39 | N39: Accessories | O39: 263659.71 | T39: Consumer | U39: 336
C40: Credit Card | D40: 1131370.5 | J40: Cable Organizer | K40: 53 | N40: Electronics | O40: 594096.63 | T40: Corporate | U40: 333
C41: Debit Card | D41: 1309456 | J41: Desk Lamp | K41: 56 | N41: Furniture | O41: 710551.6 | T41: Home Office | U41: 331
C42: Net Banking | D42: 1622114.5 | J42: Drawer Unit | K42: 47 | N42: Office Supplies | O42: 44074.3 | T42: Grand Total | U42: 1000
C43: UPI | D43: 1665896.5 | J43: File Folder | K43: 53 | N43: Grand Total | O43: 1612382.2
...

Sheet Advanced  Formulas
A1: Order ID | B1: Sales | C1: Profit | D1: Discount | E1: Performance | F1: Sales Category | G1: Customer Name | H1: Order Date | I1: Ship Date | J1: Order Status | K1: Customer Name - City
A2: {=DataSet!A2:A1001} -> ORD-2025-00001 | B2: {=DataSet!L2:L1001} -> 26000 | C2: {=DataSet!O2:O1001} -> 4901.45 | D2: {=DataSet!N2:N1001} -> 0 | E2: =IF(C2>200,"Profit","Loss") -> Profit | F2: =IF(B2>6000,"High",IF(B2>=3000,"Medium",IF(B2<3000,"Low"))) -> High | G2: =VLOOKUP(A2,DataSet!$1:$1048576,5,FALSE) -> Kiara Shah | H2: =INDEX(DataSet!B:B,MATCH('Advanced Formulas'!A2,DataSet!A:A,0)) -> 45946 | I2: =INDEX(DataSet!C:C,MATCH('Advanced Formulas'!A2,DataSet!A:A,0)) -> 45947 | J2: =IF(AND(B2>3000,C2>0),"Good Order","Review") -> Good Order | K2: =CONCATENATE(DataSet!E2,"-",DataSet!G2) -> Kiara Shah-Bhavnagar
A3: ORD-2024-00002 | B3: 102 | C3: 31.19 | D3: 0.15 | E3: =IF(C3>200,"Profit","Loss") -> Loss | F3: =IF(B3>6000,"High",IF(B3>=3000,"Medium",IF(B3<3000,"Low"))) -> Low | G3: =VLOOKUP(A3,DataSet!$1:$1048576,5,FALSE) -> Kiara Panjwani | H3: =INDEX(DataSet!B:B,MATCH('Advanced Formulas'!A3,DataSet!A:A,0)) -> 45324 | I3: =INDEX(DataSet!C:C,MATCH('Advanced Formulas'!A3,DataSet!A:A,0)) -> 45948 | J3: =IF(AND(B3>3000,C3>0),"Good Order","Review") -> Review | K3: =CONCATENATE(DataSet!E3,"-",DataSet!G3) -> Kiara Panjwani-Bhavnagar
A4: ORD-2025-00003 | B4: 6317.5 | C4: 1896.85 | D4: 0.05 | E4: =IF(C4>200,"Profit","Loss") -> Profit | F4: =IF(B4>6000,"High",IF(B4>=3000,"Medium",IF(B4<3000,"Low"))) -> High | G4: =VLOOKUP(A4,DataSet!$1:$1048576,5,FALSE) -> Aditya Shah | H4: =INDEX(DataSet!B:B,MATCH('Advanced Formulas'!A4,DataSet!A:A,0)) -> 45895 | I4: =INDEX(DataSet!C:C,MATCH('Advanced Formulas'!A4,DataSet!A:A,0)) -> 45949 | J4: =IF(AND(B4>3000,C4>0),"Good Order","Review") -> Good Order | K4: =CONCATENATE(DataSet!E4,"-",DataSet!G4) -> Aditya Shah-Hyderabad
A5: ORD-2024-00004 | B5: 15500 | C5: 2949.18 | D5: 0 | E5: =IF(C5>200,"Profit","Loss") -> Profit | F5: =IF(B5>6000,"High",IF(B5>=3000,"Medium",IF(B5<3000,"Low"))) -> High | G5: =VLOOKUP(A5,DataSet!$1:$1048576,5,FALSE) -> Anaya Sheikh | H5: =INDEX(DataSet!B:B,MATCH('Advanced Formulas'!A5,DataSet!A:A,0)) -> 45391 | I5: =INDEX(DataSet!C:C,MATCH('Advanced Formulas'!A5,DataSet!A:A,0)) -> 45950 | J5: =IF(AND(B5>3000,C5>0),"Good Order","Review") -> Good Order | K5: =CONCATENATE(DataSet!E5,"-",DataSet!G5) -> Anaya Sheikh-Kolkata
A6: ORD-2025-00005 | B6: 9920 | C6: 3292.6 | D6: 0.2 | E6: =IF(C6>200,"Profit","Loss") -> Profit | F6: =IF(B6>6000,"High",IF(B6>=3000,"Medium",IF(B6<3000,"Low"))) -> High | G6: =VLOOKUP(A6,DataSet!$1:$1048576,5,FALSE) -> Myra Iyer | H6: =INDEX(DataSet!B:B,MATCH('Advanced Formulas'!A6,DataSet!A:A,0)) -> 45857 | I6: =INDEX(DataSet!C:C,MATCH('Advanced Formulas'!A6,DataSet!A:A,0)) -> 45951 | J6: =IF(AND(B6>3000,C6>0),"Good Order","Review") -> Good Order | K6: =CONCATENATE(DataSet!E6,"-",DataSet!G6) -> Myra Iyer-Kolkata
A7: ORD-2026-00006 | B7: 2475 | C7: 494.31 | D7: 0.1 | E7: =IF(C7>200,"Profit","Loss") -> Profit | F7: =IF(B7>6000,"High",IF(B7>=3000,"Medium",IF(B7<3000,"Low"))) -> Low | G7: =VLOOKUP(A7,DataSet!$1:$1048576,5,FALSE) -> Isha Trivedi | H7: =INDEX(DataSet!B:B,MATCH('Advanced Formulas'!A7,DataSet!A:A,0)) -> 46167 | I7: =INDEX(DataSet!C:C,MATCH('Advanced Formulas'!A7,DataSet!A:A,0)) -> 45952 | J7: =IF(AND(B7>3000,C7>0),"Good Order","Review") -> Review | K7: =CONCATENATE(DataSet!E7,"-",DataSet!G7) -> Isha Trivedi-Kolkata
A8: ORD-2025-00007 | B8: 21675 | C8: 3639.82 | D8: 0.15 | E8: =IF(C8>200,"Profit","Loss") -> Profit | F8: =IF(B8>6000,"High",IF(B8>=3000,"Medium",IF(B8<3000,"Low"))) -> High | G8: =VLOOKUP(A8,DataSet!$1:$1048576,5,FALSE) -> Rohan Panjwani | H8: =INDEX(DataSet!B:B,MATCH('Advanced Formulas'!A8,DataSet!A:A,0)) -> 45978 | I8: =INDEX(DataSet!C:C,MATCH('Advanced Formulas'!A8,DataSet!A:A,0)) -> 45953 | J8: =IF(AND(B8>3000,C8>0),"Good Order","Review") -> Good Order | K8: =CONCATENATE(DataSet!E8,"-",DataSet!G8) -> Rohan Panjwani-Chennai
A9: ORD-2024-00008 | B9: 902.5 | C9: 242.05 | D9: 0.05 | E9: =IF(C9>200,"Profit","Loss") -> Profit | F9: =IF(B9>6000,"High",IF(B9>=3000,"Medium",IF(B9<3000,"Low"))) -> Low | G9: =VLOOKUP(A9,DataSet!$1:$1048576,5,FALSE) -> Reyansh Sheikh | H9: =INDEX(DataSet!B:B,MATCH('Advanced Formulas'!A9,DataSet!A:A,0)) -> 45516 | I9: =INDEX(DataSet!C:C,MATCH('Advanced Formulas'!A9,DataSet!A:A,0)) -> 45954 | J9: =IF(AND(B9>3000,C9>0),"Good Order","Review") -> Review | K9: =CONCATENATE(DataSet!E9,"-",DataSet!G9) -> Reyansh Sheikh-Mumbai
A10: ORD-2024-00009 | B10: 4560 | C10: 1533.05 | D10: 0.05 | E10: =IF(C10>200,"Profit","Loss") -> Profit | F10: =IF(B10>6000,"High",IF(B10>=3000,"Medium",IF(B10<3000,"Low"))) -> Medium | G10: =VLOOKUP(A10,DataSet!$1:$1048576,5,FALSE) -> Kiara Soni | H10: =INDEX(DataSet!B:B,MATCH('Advanced Formulas'!A10,DataSet!A:A,0)) -> 45509 | I10: =INDEX(DataSet!C:C,MATCH('Advanced Formulas'!A10,DataSet!A:A,0)) -> 45955 | J10: =IF(AND(B10>3000,C10>0),"Good Order","Review") -> Good Order | K10: =CONCATENATE(DataSet!E10,"-",DataSet!G10) -> Kiara Soni-Jaipur
A11: ORD-2025-00010 | B11: 16575 | C11: 3798.76 | D11: 0.15 | E11: =IF(C11>200,"Profit","Loss") -> Profit | F11: =IF(B11>6000,"High",IF(B11>=3000,"Medium",IF(B11<3000,"Low"))) -> High | G11: =VLOOKUP(A11,DataSet!$1:$1048576,5,FALSE) -> Diya Rao | H11: =INDEX(DataSet!B:B,MATCH('Advanced Formulas'!A11,DataSet!A:A,0)) -> 45730 | I11: =INDEX(DataSet!C:C,MATCH('Advanced Formulas'!A11,DataSet!A:A,0)) -> 45956 | J11: =IF(AND(B11>3000,C11>0),"Good Order","Review") -> Good Order | K11: =CONCATENATE(DataSet!E11,"-",DataSet!G11) -> Diya Rao-Pune
A12: ORD-2025-00011 | B12: 396 | C12: 105.25 | D12: 0.1 | E12: =IF(C12>200,"Profit","Loss") -> Loss | F12: =IF(B12>6000,"High",IF(B12>=3000,"Medium",IF(B12<3000,"Low"))) -> Low | G12: =VLOOKUP(A12,DataSet!$1:$1048576,5,FALSE) -> Dev Joshi | H12: =INDEX(DataSet!B:B,MATCH('Advanced Formulas'!A12,DataSet!A:A,0)) -> 45934 | I12: =INDEX(DataSet!C:C,MATCH('Advanced Formulas'!A12,DataSet!A:A,0)) -> 45957 | J12: =IF(AND(B12>3000,C12>0),"Good Order","Review") -> Review | K12: =CONCATENATE(DataSet!E12,"-",DataSet!G12) -> Dev Joshi-Hyderabad
A13: ORD-2025-00012 | B13: 5320 | C13: 1380.33 | D13: 0.05 | E13: =IF(C13>200,"Profit","Loss") -> Profit | F13: =IF(B13>6000,"High",IF(B13>=3000,"Medium",IF(B13<3000,"Low"))) -> Medium | G13: =VLOOKUP(A13,DataSet!$1:$1048576,5,FALSE) -> Aarav Verma | H13: =INDEX(DataSet!B:B,MATCH('Advanced Formulas'!A13,DataSet!A:A,0)) -> 45988 | I13: =INDEX(DataSet!C:C,MATCH('Advanced Formulas'!A13,DataSet!A:A,0)) -> 45958 | J13: =IF(AND(B13>3000,C13>0),"Good Order","Review") -> Good Order | K13: =CONCATENATE(DataSet!E13,"-",DataSet!G13) -> Aarav Verma-Bhavnagar
A14: ORD-2026-00013 | B14: 144 | C14: 39.23 | D14: 0.2 | E14: =IF(C14>200,"Profit","Loss") -> Loss | F14: =IF(B14>6000,"High",IF(B14>=3000,"Medium",IF(B14<3000,"Low"))) -> Low | G14: =VLOOKUP(A14,DataSet!$1:$1048576,5,FALSE) -> Dev Dave | H14: =INDEX(DataSet!B:B,MATCH('Advanced Formulas'!A14,DataSet!A:A,0)) -> 46287 | I14: =INDEX(DataSet!C:C,MATCH('Advanced Formulas'!A14,DataSet!A:A,0)) -> 45959 | J14: =IF(AND(B14>3000,C14>0),"Good Order","Review") -> Review | K14: =CONCATENATE(DataSet!E14,"-",DataSet!G14) -> Dev Dave-Hyderabad
... A1001: ORD-2024-01000 | B1001: 720 | C1001: 138.2 | D1001: 0.2 | E1001: =IF(C1001>200,"Profit","Loss") -> Loss | F1001: =IF(B1001>6000,"High",IF(B1001>=3000,"Medium",IF(B1001<3000,"Low"))) -> Low | G1001: =VLOOKUP(A1001,DataSet!$1:$1048576,5,FALSE) -> Kabir Dave | H1001: =INDEX(DataSet!B:B,MATCH('Advanced Formulas'!A1001,DataSet!A:A,0)) -> 45582 | I1001: =INDEX(DataSet!C:C,MATCH('Advanced Formulas'!A1001,DataSet!A:A,0)) -> 45587 | J1001: =IF(AND(B1001>3000,C1001>0),"Good Order","Review") -> Review | K1001: =CONCATENATE(DataSet!E1001,"-",DataSet!G1001) -> Kabir Dave-Vadodara
